2018-05-21 09:19:11,513 _internal.py[line:88] WARNING  * Debugger is active!
2018-05-21 14:21:23,524 _internal.py[line:88] WARNING  * Debugger is active!
2018-05-21 14:24:23,823 _internal.py[line:88] WARNING  * Debugger is active!
2018-05-21 14:29:18,431 _internal.py[line:88] WARNING  * Debugger is active!
2018-05-21 14:30:43,868 _internal.py[line:88] WARNING  * Debugger is active!
2018-05-21 14:35:40,871 _internal.py[line:88] WARNING  * Debugger is active!
2018-05-21 14:36:18,458 _internal.py[line:88] WARNING  * Debugger is active!
2018-05-21 14:41:43,857 _internal.py[line:88] WARNING  * Debugger is active!
2018-05-21 14:41:49,410 server.py[line:413] ERROR message handler error
Traceback (most recent call last):
  File "/Users/liduo/Envs/flask0.10.1_py2/lib/python2.7/site-packages/engineio/server.py", line 411, in _trigger_event
    return self.handlers[event](*args)
  File "/Users/liduo/Envs/flask0.10.1_py2/lib/python2.7/site-packages/socketio/server.py", line 522, in _handle_eio_message
    self._handle_event(sid, pkt.namespace, pkt.id, pkt.data)
  File "/Users/liduo/Envs/flask0.10.1_py2/lib/python2.7/site-packages/socketio/server.py", line 458, in _handle_event
    self._handle_event_internal(self, sid, data, namespace, id)
  File "/Users/liduo/Envs/flask0.10.1_py2/lib/python2.7/site-packages/socketio/server.py", line 461, in _handle_event_internal
    r = server._trigger_event(data[0], namespace, sid, *data[1:])
  File "/Users/liduo/Envs/flask0.10.1_py2/lib/python2.7/site-packages/socketio/server.py", line 490, in _trigger_event
    return self.handlers[namespace][event](*args)
  File "/Users/liduo/Envs/flask0.10.1_py2/lib/python2.7/site-packages/flask_socketio/__init__.py", line 251, in _handler
    *args)
  File "/Users/liduo/Envs/flask0.10.1_py2/lib/python2.7/site-packages/flask_socketio/__init__.py", line 634, in _handle_event
    ret = handler(*args)
  File "/Users/liduo/PycharmProjects/flask_socketio/apps/api/views_socket_io.py", line 35, in socket
    data_mine.username = data_mine.get("username")
AttributeError: 'dict' object has no attribute 'username'
2018-05-21 14:44:06,400 _internal.py[line:88] WARNING  * Debugger is active!
2018-05-21 14:45:14,188 _internal.py[line:88] WARNING  * Debugger is active!
2018-05-21 14:45:24,874 server.py[line:413] ERROR message handler error
Traceback (most recent call last):
  File "/Users/liduo/Envs/flask0.10.1_py2/lib/python2.7/site-packages/engineio/server.py", line 411, in _trigger_event
    return self.handlers[event](*args)
  File "/Users/liduo/Envs/flask0.10.1_py2/lib/python2.7/site-packages/socketio/server.py", line 522, in _handle_eio_message
    self._handle_event(sid, pkt.namespace, pkt.id, pkt.data)
  File "/Users/liduo/Envs/flask0.10.1_py2/lib/python2.7/site-packages/socketio/server.py", line 458, in _handle_event
    self._handle_event_internal(self, sid, data, namespace, id)
  File "/Users/liduo/Envs/flask0.10.1_py2/lib/python2.7/site-packages/socketio/server.py", line 461, in _handle_event_internal
    r = server._trigger_event(data[0], namespace, sid, *data[1:])
  File "/Users/liduo/Envs/flask0.10.1_py2/lib/python2.7/site-packages/socketio/server.py", line 490, in _trigger_event
    return self.handlers[namespace][event](*args)
  File "/Users/liduo/Envs/flask0.10.1_py2/lib/python2.7/site-packages/flask_socketio/__init__.py", line 251, in _handler
    *args)
  File "/Users/liduo/Envs/flask0.10.1_py2/lib/python2.7/site-packages/flask_socketio/__init__.py", line 634, in _handle_event
    ret = handler(*args)
  File "/Users/liduo/PycharmProjects/flask_socketio/apps/api/views_socket_io.py", line 49, in socket
    print(data_mine_username.decode(), data_mine_mine, data_mine_content, data_mine_avatar, data_mine_id)
UnicodeEncodeError: 'ascii' codec can't encode characters in position 0-2: ordinal not in range(128)
2018-05-21 14:45:49,476 _internal.py[line:88] WARNING  * Debugger is active!
2018-05-21 14:48:51,653 _internal.py[line:88] WARNING  * Debugger is active!
2018-05-21 14:48:58,221 server.py[line:413] ERROR message handler error
Traceback (most recent call last):
  File "/Users/liduo/Envs/flask0.10.1_py2/lib/python2.7/site-packages/engineio/server.py", line 411, in _trigger_event
    return self.handlers[event](*args)
  File "/Users/liduo/Envs/flask0.10.1_py2/lib/python2.7/site-packages/socketio/server.py", line 522, in _handle_eio_message
    self._handle_event(sid, pkt.namespace, pkt.id, pkt.data)
  File "/Users/liduo/Envs/flask0.10.1_py2/lib/python2.7/site-packages/socketio/server.py", line 458, in _handle_event
    self._handle_event_internal(self, sid, data, namespace, id)
  File "/Users/liduo/Envs/flask0.10.1_py2/lib/python2.7/site-packages/socketio/server.py", line 461, in _handle_event_internal
    r = server._trigger_event(data[0], namespace, sid, *data[1:])
  File "/Users/liduo/Envs/flask0.10.1_py2/lib/python2.7/site-packages/socketio/server.py", line 490, in _trigger_event
    return self.handlers[namespace][event](*args)
  File "/Users/liduo/Envs/flask0.10.1_py2/lib/python2.7/site-packages/flask_socketio/__init__.py", line 251, in _handler
    *args)
  File "/Users/liduo/Envs/flask0.10.1_py2/lib/python2.7/site-packages/flask_socketio/__init__.py", line 634, in _handle_event
    ret = handler(*args)
  File "/Users/liduo/PycharmProjects/flask_socketio/apps/api/views_socket_io.py", line 49, in socket
    print(data_mine_username.decode("ascii"), data_mine_mine, data_mine_content, data_mine_avatar, data_mine_id)
UnicodeEncodeError: 'ascii' codec can't encode characters in position 0-2: ordinal not in range(128)
2018-05-21 14:49:10,651 _internal.py[line:88] WARNING  * Debugger is active!
2018-05-21 14:49:55,913 _internal.py[line:88] WARNING  * Debugger is active!
2018-05-21 14:50:01,862 server.py[line:413] ERROR message handler error
Traceback (most recent call last):
  File "/Users/liduo/Envs/flask0.10.1_py2/lib/python2.7/site-packages/engineio/server.py", line 411, in _trigger_event
    return self.handlers[event](*args)
  File "/Users/liduo/Envs/flask0.10.1_py2/lib/python2.7/site-packages/socketio/server.py", line 522, in _handle_eio_message
    self._handle_event(sid, pkt.namespace, pkt.id, pkt.data)
  File "/Users/liduo/Envs/flask0.10.1_py2/lib/python2.7/site-packages/socketio/server.py", line 458, in _handle_event
    self._handle_event_internal(self, sid, data, namespace, id)
  File "/Users/liduo/Envs/flask0.10.1_py2/lib/python2.7/site-packages/socketio/server.py", line 461, in _handle_event_internal
    r = server._trigger_event(data[0], namespace, sid, *data[1:])
  File "/Users/liduo/Envs/flask0.10.1_py2/lib/python2.7/site-packages/socketio/server.py", line 490, in _trigger_event
    return self.handlers[namespace][event](*args)
  File "/Users/liduo/Envs/flask0.10.1_py2/lib/python2.7/site-packages/flask_socketio/__init__.py", line 251, in _handler
    *args)
  File "/Users/liduo/Envs/flask0.10.1_py2/lib/python2.7/site-packages/flask_socketio/__init__.py", line 634, in _handle_event
    ret = handler(*args)
  File "/Users/liduo/PycharmProjects/flask_socketio/apps/api/views_socket_io.py", line 49, in socket
    print(data_mine_username.encode(), data_mine_mine, data_mine_content, data_mine_avatar, data_mine_id)
UnicodeEncodeError: 'ascii' codec can't encode characters in position 0-2: ordinal not in range(128)
2018-05-21 14:50:19,417 _internal.py[line:88] WARNING  * Debugger is active!
2018-05-21 14:51:06,952 _internal.py[line:88] WARNING  * Debugger is active!
2018-05-21 14:52:16,946 _internal.py[line:88] WARNING  * Debugger is active!
2018-05-21 14:52:48,120 _internal.py[line:88] WARNING  * Debugger is active!
2018-05-21 14:53:12,150 _internal.py[line:88] WARNING  * Debugger is active!
2018-05-21 14:53:21,880 _internal.py[line:88] WARNING  * Debugger is active!
2018-05-21 14:55:33,202 _internal.py[line:88] WARNING  * Debugger is active!
2018-05-21 14:55:54,193 _internal.py[line:88] WARNING  * Debugger is active!
2018-05-21 14:59:29,252 _internal.py[line:88] WARNING  * Debugger is active!
2018-05-21 15:01:42,752 _internal.py[line:88] WARNING  * Debugger is active!
2018-05-21 15:02:47,730 _internal.py[line:88] WARNING  * Debugger is active!
2018-05-21 15:14:18,722 _internal.py[line:88] WARNING  * Debugger is active!
2018-05-21 15:17:32,542 _internal.py[line:88] WARNING  * Debugger is active!
2018-05-21 15:24:53,439 _internal.py[line:88] WARNING  * Debugger is active!
2018-05-21 15:26:34,152 _internal.py[line:88] WARNING  * Debugger is active!
2018-05-21 15:27:06,406 _internal.py[line:88] WARNING  * Debugger is active!
2018-05-21 15:36:40,849 _internal.py[line:88] WARNING  * Debugger is active!
2018-05-21 15:37:32,492 _internal.py[line:88] WARNING  * Debugger is active!
2018-05-21 15:38:21,093 _internal.py[line:88] WARNING  * Debugger is active!
2018-05-21 15:45:21,556 _internal.py[line:88] WARNING  * Debugger is active!
2018-05-21 15:49:52,998 _internal.py[line:88] WARNING  * Debugger is active!
2018-05-21 15:53:39,314 _internal.py[line:88] WARNING  * Debugger is active!
2018-05-21 18:30:07,517 _internal.py[line:88] WARNING  * Debugger is active!
